<?xml version="1.0" encoding="utf-8"?>
<robot name="Jonny">
  <material name="default">
    <color rgba="0.2 0.2 0.2 1.0"/>
  </material>
  <link name="world"/>
  <joint name="base_joint" type="fixed">
    <parent link="world"/>
    <child link="link_0"/>
    <origin rpy="0 0 0" xyz="0 0 0"/>
    <axis xyz="0 0 1"/>
  </joint>
  <link
    name="link_0">
    <visual>
      <origin
        xyz="0 0 0"
        rpy="0 0 0" />
      <geometry>
        <mesh
          filename="package://jonny_robot_description/meshes/link_0.STL" />
      </geometry>
      <material name="default"/>
    </visual>
    <collision>
      <origin
        xyz="0 0 0"
        rpy="0 0 0" />
      <geometry>
        <mesh
          filename="package://jonny_robot_description/meshes/link_0.STL" />
      </geometry>
    </collision>
  </link>
  <link
    name="link_1">
    <visual>
      <origin
        xyz="0 0 0"
        rpy="0 0 0" />
      <geometry>
        <mesh
          filename="package://jonny_robot_description/meshes/link_1.STL" />
      </geometry>
      <material name="default"/>
    </visual>
    <collision>
      <origin
        xyz="0 0 0"
        rpy="0 0 0" />
      <geometry>
        <mesh
          filename="package://jonny_robot_description/meshes/link_1.STL" />
      </geometry>
    </collision>
  </link>
  <link
    name="link_2">
    <visual>
      <origin
        xyz="0 0 0"
        rpy="0 0 0" />
      <geometry>
        <mesh
          filename="package://jonny_robot_description/meshes/link_2.STL" />
      </geometry>
      <material name="default"/>
    </visual>
    <collision>
      <origin
        xyz="0 0 0"
        rpy="0 0 0" />
      <geometry>
        <mesh
          filename="package://jonny_robot_description/meshes/link_2.STL" />
      </geometry>
    </collision>
  </link>
  <link
    name="link_3">
    <visual>
      <origin
        xyz="0 0 0"
        rpy="0 0 0" />
      <geometry>
        <mesh
          filename="package://jonny_robot_description/meshes/link_3.STL" />
      </geometry>
      <material name="default"/>
    </visual>
    <collision>
      <origin
        xyz="0 0 0"
        rpy="0 0 0" />
      <geometry>
        <mesh
          filename="package://jonny_robot_description/meshes/link_3.STL" />
      </geometry>
    </collision>
  </link>
  <link
    name="link_4">
    <visual>
      <origin
        xyz="0 0 0"
        rpy="0 0 0" />
      <geometry>
        <mesh
          filename="package://jonny_robot_description/meshes/link_4.STL" />
      </geometry>
      <material name="default"/>
    </visual>
    <collision>
      <origin
        xyz="0 0 0"
        rpy="0 0 0" />
      <geometry>
        <mesh
          filename="package://jonny_robot_description/meshes/link_4.STL" />
      </geometry>
    </collision>
  </link>
  <link
    name="link_5">
    <visual>
      <origin
        xyz="0 0 0"
        rpy="0 0 0" />
      <geometry>
        <mesh
          filename="package://jonny_robot_description/meshes/link_5.STL" />
      </geometry>
      <material name="default"/>
    </visual>
    <collision>
      <origin
        xyz="0 0 0"
        rpy="0 0 0" />
      <geometry>
        <mesh
          filename="package://jonny_robot_description/meshes/link_5.STL" />
      </geometry>
    </collision>
  </link>
  <link
    name="link_6">
    <visual>
      <origin
        xyz="0 0 0"
        rpy="0 0 0" />
      <geometry>
        <mesh
          filename="package://jonny_robot_description/meshes/link_6.STL" />
      </geometry>
      <material name="default"/>
    </visual>
    <collision>
      <origin
        xyz="0 0 0"
        rpy="0 0 0" />
      <geometry>
        <mesh
          filename="package://jonny_robot_description/meshes/link_6.STL" />
      </geometry>
    </collision>
  </link>
  <joint
    name="joint_1"
    type="revolute">
    <origin
      xyz="0 0 0.043358"
      rpy="1.5708 0 0.035851" />
    <parent
      link="link_0" />
    <child
      link="link_1" />
    <axis
      xyz="0 1 0" />
    <limit
      lower="-3.14"
      upper="3.14"
      effort="0"
      velocity="0" />
  </joint>
  <joint
    name="joint_2"
    type="revolute">
    <origin
      xyz="0 0.23664 0"
      rpy="0 0 0" />
    <parent
      link="link_1" />
    <child
      link="link_2" />
    <axis
      xyz="0 0 1" />
    <limit
      lower="-1.57"
      upper="1.57"
      effort="0"
      velocity="0" />
  </joint>
  <joint
    name="joint_3"
    type="revolute">
    <origin
      xyz="0 0.26 0"
      rpy="0 0 0" />
    <parent
      link="link_2" />
    <child
      link="link_3" />
    <axis
      xyz="0 0 -1" />
    <limit
      lower="-2.0944"
      upper="2.0944"
      effort="0"
      velocity="0" />
  </joint>
  <joint
    name="joint_4"
    type="revolute">
    <origin
      xyz="0 0.1538 0"
      rpy="0 -0.035851 0" />
    <parent
      link="link_3" />
    <child
      link="link_4" />
    <axis
      xyz="0 -1 0" />
    <limit
      lower="-1.57"
      upper="1.57"
      effort="0"
      velocity="0" />
  </joint>
  <joint
    name="joint_5"
    type="revolute">
    <origin
      xyz="0 0.1652 0"
      rpy="0 0 0" />
    <parent
      link="link_4" />
    <child
      link="link_5" />
    <axis
      xyz="0 0 -1" />
    <limit
      lower="-1.57"
      upper="1.57"
      effort="0"
      velocity="0" />
  </joint>
  <joint
    name="joint_6"
    type="revolute">
    <origin
      xyz="0 0.0408 0.0003"
      rpy="0 0 0" />
    <parent
      link="link_5" />
    <child
      link="link_6" />
    <axis
      xyz="0 -1 0" />
    <limit
      lower="-3.14"
      upper="3.14"
      effort="0"
      velocity="0" />
  </joint>
</robot>
